<?xml version="1.0"?>

<robot name="robot" xmlns:xacro="http://www.ros.org/wiki/xacro">

  <!-- <xacro:include filename="$(find robot_description)/urdf/robot.gazebo" /> -->

<!-- Material Definitions -->
  <material name="black">
    <color rgba="0 0 0 1"/>
  </material>

  <material name="grey">
    <color rgba="0.5 0.5 0.5 0.7"/>
  </material>

  <material name="blue">
    <color rgba="0 0 1 0.5"/>
  </material>
  
 
  <!-- Base link -->
    <gazebo reference="base_link">
        <material>Gazebo/Black</material>
    </gazebo>

  <link name="base_link">
    <inertial>
      <origin xyz="0 0 0" rpy="0 0 0"/>
      <mass value="25"/> <!-- Robot weight 25 kg -->
      <!-- moment of inertia for cylinder: 1/12*m*(3*r^2 + h^2) for ixx and iyy, 
      1/2 * m * r^2 for izz (r=0.25 and m=25)-->
      <inertia ixx="1.3" ixy="0" ixz="0" iyy="1.3" iyz="0" izz="0.52"/>
    </inertial>
    <visual>
      <origin xyz="0 0 0" rpy="0 0 0"/>
      <geometry>
        <cylinder radius="0.25" length="0.3"/>
      </geometry>
      <material name="blue"/>
    </visual>
    <collision>
      <origin xyz="0 0 0" rpy="0 0 0"/>
      <geometry>
        <cylinder radius="0.25" length="0.3"/>
      </geometry>
    </collision>
  </link>


<!--Wheel Left-->
  <joint name="left_wheel_joint" type="continuous">
    <parent link="base_link"/>
    <child link="left_wheel"/>
    <origin xyz="0.0 -0.2 -0.15" rpy="0 0 0"/>
    <axis xyz="0 1 0"/>
    <limit effort="10000" velocity="1000" />
    <joint_properties damping="1.0" friction="1.0" />
  </joint>

  <link name="left_wheel">
    <inertial>
        <mass value="1" />
        <origin xyz="0 0 0" rpy="0 0 0" />
        <inertia ixx="0.002526666666667" ixy="0" ixz="0" iyy="0.002526666666667" iyz="0" izz="0.005"/>
    </inertial>
    <collision>
        <origin rpy="0 0 0" xyz="0 0 0" />
        <geometry>
            <cylinder length="0.05" radius="0.025"/>
        </geometry>
    </collision>
    <visual>
      <origin xyz="0 0 0" rpy="0 0 0"/>
      <geometry>
        <cylinder radius="0.025" length="0.05"/>
      </geometry>
      <material name="black"/>
    </visual>
  </link>

<!--Wheel Right-->
  <joint name="right_wheel_joint" type="continuous">
    <parent link="base_link"/>
    <child link="right_wheel"/>
    <origin xyz="0.0 -0.2 -0.15" rpy="0 0 0"/>
    <axis xyz="0 1 0"/>
    <limit effort="10000" velocity="1000" />
    <joint_properties damping="1.0" friction="1.0" />
  </joint>

  <link name="right_wheel">
    <inertial>
        <mass value="1" />
        <origin xyz="0 0 0" rpy="0 0 0" />
        <inertia ixx="0.002526666666667" ixy="0" ixz="0" iyy="0.002526666666667" iyz="0" izz="0.005"/>
    </inertial>
    <collision>
        <origin rpy="0 0 0" xyz="0 0 0" />
        <geometry>
            <cylinder length="0.05" radius="0.025"/>
        </geometry>
    </collision>
    <visual>
      <origin xyz="0 0 0" rpy="0 0 0"/>
      <geometry>
        <cylinder radius="0.025" length="0.05"/>
      </geometry>
      <material name="black"/>
    </visual>
  </link>


  <!-- caster wheel -->
  <joint name="front_caster_joint" type="fixed">
    <parent link="base_link"/>
    <child link="front_caster"/>
    <origin xyz="-0.1 0 -0.15" rpy="0 0 0"/>
  </joint>

  <link name="front_caster">
    <visual>
      <origin xyz="0 0 0" rpy="0 0 0"/>
      <geometry>
        <sphere radius="0.0125"/>
      </geometry>
      <material name="grey"/>
    </visual>
  </link>

  <joint name="back_caster_joint" type="fixed">
    <parent link="base_link"/>
    <child link="back_caster"/>
    <origin xyz="0.1 0 -0.15" rpy="0 0 0"/>
  </joint>

  <link name="back_caster">
    <visual>
      <origin xyz="0 0 0" rpy="0 0 0"/>
      <geometry>
        <sphere radius="0.0125"/>
      </geometry>
      <material name="grey"/>
    </visual>
  </link>


    <gazebo>
        <plugin filename="libgazebo_ros_diff_drive.so" name="differential_drive_controller">
            <alwaysOn>true</alwaysOn>
            <!-- Set the update rate in Hz -->
            <updateRate>20.0</updateRate>

            <!-- Name of the left joint -->
            <leftJoint>left_wheel_joint</leftJoint>

            <!-- Name of the right joint -->
            <rightJoint>right_wheel_joint</rightJoint>

            <!-- The distance from the center of one wheel to the other, in meters -->
            <wheelSeparation>0.4</wheelSeparation>

            <!-- Diameter of the wheels, in meters -->
            <wheelDiameter>0.05</wheelDiameter>

            <!-- Wheel acceleration, in rad/s^2 -->
            <wheelAcceleration>1.0</wheelAcceleration>

            <!-- Maximum torque which the wheels can produce, in Nm -->
            <wheelTorque>20</wheelTorque>

            <!-- Topic to receive geometry_msgs/Twist message commands -->
            <commandTopic>/cmd_vel</commandTopic>

            <!-- Topic to publish nav_msgs/Odometry messages -->
            <odometryTopic>odom</odometryTopic>

            <!-- Odometry frame -->
            <odometryFrame>odom</odometryFrame>

            <!-- Robot frame to calculate odometry from -->
            <robotBaseFrame>base_link</robotBaseFrame>

            <!-- Set to true to publish transforms for the wheel links -->
            <publishWheelTF>true</publishWheelTF>

            <!-- Set to true to publish transforms for the odometry -->
            <!-- <publishOdom>true</publishOdom> -->

            <!-- Set to true to publish sensor_msgs/JointState on /joint_states for the wheel joints -->
            <!-- <publishWheelJointState>true</publishWheelJointState> -->

            <!-- Set to true to swap right and left wheels -->
            <!-- <legacyMode>false</legacyMode> -->

            <!-- Set the debug level -->
            <rosDebugLevel>debug</rosDebugLevel>

            <!-- Publish odometry transforms -->
            <!-- <publishOdomTF>true</publishOdomTF> -->

            <!-- Specify the odometry source -->
            <!-- <odometrySource>1</odometrySource> -->
        </plugin>
    </gazebo>



    <!-- Gazebo tags - Laser scan -->
    <gazebo reference="joint_laser_scan_chassis">
        <preserveFixedJoint>true</preserveFixedJoint>
    </gazebo>
    <gazebo reference="link_laser_scan">
        <material>Gazebo/DarkGrey</material>
    </gazebo>

    <!-- Laser scan -->
    <joint name="joint_laser_scan_chassis" type="fixed">
        <origin xyz="0.25 0 0.075" rpy="3.14159 0 0"/> <!--laser upside down by pi radians-->
        <child link="link_laser_scan" />
        <parent link="base_link" />
        <joint_properties damping="1.0" friction="1.0" />
    </joint>
    <link name="link_laser_scan">
        <inertial>
            <origin xyz="0 0 0" rpy="0 0 0" />
            <mass value="0.5" />
            <inertia ixx="0.000252666666667" ixy="0" ixz="0" iyy="0.000252666666667" iyz="0" izz="0.0005"/>
        </inertial>
        <visual>
            <origin xyz="0 0 0" rpy="0 0 0" />
            <geometry>
                <cylinder radius="0.05" length="0.075"/>
            </geometry>
            <material name="Red">
                <color rgba="0.7 0.1 0.1 1" />
            </material>
        </visual>
        <collision>
            <origin xyz="0 0 0" rpy="0 0 0"/>
            <geometry>
                <cylinder radius="0.05" length="0.075"/>
            </geometry>
        </collision>
    </link>

    <gazebo reference="link_laser_scan">
        <sensor type="ray" name="head_hokuyo_sensor">
            <pose>0 0 0 0 0 0</pose>
            <visualize>true</visualize>
            <update_rate>20</update_rate>
            <ray>
                <scan>
                    <horizontal>
                        <samples>720</samples>
                        <resolution>1</resolution>
                        <min_angle>-1.570796</min_angle>
                        <max_angle>1.570796</max_angle>
                    </horizontal>
                </scan>
                <range>
                    <min>0.20</min>
                    <max>10.0</max>
                    <resolution>0.01</resolution>
                </range>
                <noise>
                    <type>gaussian</type>
                    <mean>0.0</mean>
                    <stddev>0.01</stddev>
                </noise>
            </ray>
            <plugin name="gazebo_ros_head_hokuyo_controller" filename="libgazebo_ros_laser.so">
                <topicName>/scan</topicName>
                <frameName>sensor_laser</frameName>
            </plugin>
        </sensor>
    </gazebo>


</robot>